<?xml version="1.0" encoding="UTF-8"?>
<testng-results skipped="0" failed="1" ignored="0" total="2" passed="1">
  <reporter-output>
    <line>
      <![CDATA[Jenkins is Cool]]>
    </line>
    <line>
      <![CDATA[Jenkins is continous integration and deployment Tool]]>
    </line>
    <line>
      <![CDATA[Jenkins Failed Test Casel]]>
    </line>
  </reporter-output>
  <suite name="Suite" duration-ms="9301" started-at="2020-12-31T04:51:02Z" finished-at="2020-12-31T04:51:11Z">
    <groups>
    </groups>
    <test name="Test" duration-ms="9301" started-at="2020-12-31T04:51:02Z" finished-at="2020-12-31T04:51:11Z">
      <class name="JenkinsPratice.P2">
        <test-method status="FAIL" signature="tc_02()[pri:0, instance:JenkinsPratice.P2@170c109]" name="tc_02" duration-ms="12" started-at="2020-12-31T04:51:11Z" finished-at="2020-12-31T04:51:11Z">
          <exception class="java.lang.AssertionError">
            <message>
              <![CDATA[null]]>
            </message>
            <full-stacktrace>
              <![CDATA[java.lang.AssertionError: null
at org.testng.Assert.fail(Assert.java:96)
at org.testng.Assert.fail(Assert.java:103)
at JenkinsPratice.P2.tc_02(P2.java:13)
at sun.reflect.NativeMethodAccessorImpl.invoke0(Native Method)
at sun.reflect.NativeMethodAccessorImpl.invoke(NativeMethodAccessorImpl.java:62)
at sun.reflect.DelegatingMethodAccessorImpl.invoke(DelegatingMethodAccessorImpl.java:43)
at java.lang.reflect.Method.invoke(Method.java:498)
at org.testng.internal.MethodInvocationHelper.invokeMethod(MethodInvocationHelper.java:124)
at org.testng.internal.Invoker.invokeMethod(Invoker.java:583)
at org.testng.internal.Invoker.invokeTestMethod(Invoker.java:719)
at org.testng.internal.Invoker.invokeTestMethods(Invoker.java:989)
at org.testng.internal.TestMethodWorker.invokeTestMethods(TestMethodWorker.java:125)
at org.testng.internal.TestMethodWorker.run(TestMethodWorker.java:109)
at org.testng.TestRunner.privateRun(TestRunner.java:648)
at org.testng.TestRunner.run(TestRunner.java:505)
at org.testng.SuiteRunner.runTest(SuiteRunner.java:455)
at org.testng.SuiteRunner.runSequentially(SuiteRunner.java:450)
at org.testng.SuiteRunner.privateRun(SuiteRunner.java:415)
at org.testng.SuiteRunner.run(SuiteRunner.java:364)
at org.testng.SuiteRunnerWorker.runSuite(SuiteRunnerWorker.java:52)
at org.testng.SuiteRunnerWorker.run(SuiteRunnerWorker.java:84)
at org.testng.TestNG.runSuitesSequentially(TestNG.java:1208)
at org.testng.TestNG.runSuitesLocally(TestNG.java:1137)
at org.testng.TestNG.runSuites(TestNG.java:1049)
at org.testng.TestNG.run(TestNG.java:1017)
at org.testng.TestNG.privateMain(TestNG.java:1354)
at org.testng.TestNG.main(TestNG.java:1323)
]]>
            </full-stacktrace>
          </exception> <!-- java.lang.AssertionError -->
          <reporter-output>
            <line>
              <![CDATA[Jenkins Failed Test Casel]]>
            </line>
          </reporter-output>
        </test-method> <!-- tc_02 -->
      </class> <!-- JenkinsPratice.P2 -->
      <class name="JenkinsPratice.P1">
        <test-method status="PASS" signature="tc_01()[pri:0, instance:JenkinsPratice.P1@1e94b0f]" name="tc_01" duration-ms="9266" started-at="2020-12-31T04:51:02Z" finished-at="2020-12-31T04:51:11Z">
          <reporter-output>
            <line>
              <![CDATA[Jenkins is Cool]]>
            </line>
            <line>
              <![CDATA[Jenkins is continous integration and deployment Tool]]>
            </line>
          </reporter-output>
        </test-method> <!-- tc_01 -->
      </class> <!-- JenkinsPratice.P1 -->
    </test> <!-- Test -->
  </suite> <!-- Suite -->
</testng-results>
